<?xml version="1.0" encoding="utf-8"?>
<!-- This URDF was automatically created by SolidWorks to URDF Exporter! Originally created by Stephen Brawner (brawner@gmail.com) 
     Commit Version: 1.5.1-0-g916b5db  Build Version: 1.5.7152.31018
     For more information, please see http://wiki.ros.org/sw_urdf_exporter -->
<robot
  name="robotpincher">
 <!-- Used for fixing robot to Gazebo 'base_link' -->
<!--link name="world"/> <joint name="fixed" type="fixed"> <parent link="world"/> <child link="base_link"/> </joint>-->

 <link
    name="base_link">
    <inertial>
      <origin
        xyz="-3.0003E-12 0.028128 -0.011116"
        rpy="0 0 0" />
      <mass
        value="0.12147" />
      <inertia
        ixx="0.00017253"
        ixy="-1.4609E-15"
        ixz="5.2081E-15"
        iyy="0.00015924"
        iyz="8.6917E-06"
        izz="0.00024303" />
    </inertial>
    <visual>
      <origin
        xyz="0 0 0"
        rpy="0 0 0" />
      <geometry>
        <mesh
          filename="package://robotpincher/meshes/base_link.STL" />
      </geometry>
      <material
        name="">
        <color
          rgba="0.79216 0.81961 0.93333 1" />
      </material>
    </visual>
    <collision>
      <origin
        xyz="0 0 0"
        rpy="0 0 0" />
      <geometry>
        <mesh
          filename="package://robotpincher/meshes/base_link.STL" />
      </geometry>
    </collision>
  </link>
  <link
    name="Link1">
    <inertial>
      <origin
        xyz="-0.00096532 -6.2613E-12 0.067704"
        rpy="0 0 0" />
      <mass
        value="0.045584" />
      <inertia
        ixx="1.0435E-05"
        ixy="-5.2081E-15"
        ixz="-2.5269E-07"
        iyy="1.2447E-05"
        iyz="1.4608E-15"
        izz="7.1283E-06" />
    </inertial>
    <visual>
      <origin
        xyz="0 0 0"
        rpy="0 0 0" />
      <geometry>
        <mesh
          filename="package://robotpincher/meshes/Link1.STL" />
      </geometry>
      <material
        name="">
        <color
          rgba="0.79216 0.81961 0.93333 1" />
      </material>
    </visual>
    <collision>
      <origin
        xyz="0 0 0"
        rpy="0 0 0" />
      <geometry>
        <mesh
          filename="package://robotpincher/meshes/Link1.STL" />
      </geometry>
    </collision>
  </link>
  <joint
    name="Joint1"
    type="revolute">
    <origin
      xyz="0 0 0"
      rpy="0 0 0" />
    <parent
      link="base_link" />
    <child
      link="Link1" />
    <axis
      xyz="0 0 1" />
    <limit
      lower="-1.5708"
      upper="1.5708"
      effort="1000"
      velocity="0.5" />
  </joint>

<transmission name="tran1">
    <type>transmission_interface/SimpleTransmission</type>
    <joint name="Joint1">
	<hardwareInterface>EffortJointInterface</hardwareInterface>
    </joint>
    <actuator name="motor1">
      <hardwareInterface>EffortJointInterface</hardwareInterface>
      <mechanicalReduction>1</mechanicalReduction>
    </actuator>
  </transmission>

  <link
    name="Link2">
    <inertial>
      <origin
        xyz="0.081532 -4.4146E-12 0.00071738"
        rpy="0 0 0" />
      <mass
        value="0.064652" />
      <inertia
        ixx="1.1916E-05"
        ixy="1.4609E-15"
        ixz="3.2612E-07"
        iyy="1.8721E-05"
        iyz="5.2081E-15"
        izz="1.3966E-05" />
    </inertial>
    <visual>
      <origin
        xyz="0 0 0"
        rpy="0 0 0" />
      <geometry>
        <mesh
          filename="package://robotpincher/meshes/Link2.STL" />
      </geometry>
      <material
        name="">
        <color
          rgba="0.79216 0.81961 0.93333 1" />
      </material>
    </visual>
    <collision>
      <origin
        xyz="0 0 0"
        rpy="0 0 0" />
      <geometry>
        <mesh
          filename="package://robotpincher/meshes/Link2.STL" />
      </geometry>
    </collision>
  </link>
  <joint
    name="Joint2"
    type="revolute">
    <origin
      xyz="0 0 0.080912"
      rpy="3.1416 -1.5708 0" />
    <parent
      link="Link1" />
    <child
      link="Link2" />
    <axis
      xyz="0 0 -1" />
    <limit
     lower="-1.5708"
      upper="1.5708"
      effort="1000"
      velocity="0.5" />
  </joint>

<transmission name="tran2">
    <type>transmission_interface/SimpleTransmission</type>
    <joint name="Joint2">
	<hardwareInterface>EffortJointInterface</hardwareInterface>
    </joint>
    <actuator name="motor2">
      <hardwareInterface>EffortJointInterface</hardwareInterface>
      <mechanicalReduction>1</mechanicalReduction>
    </actuator>
  </transmission>

  <link
    name="Link3">
    <inertial>
      <origin
        xyz="0.081532 -4.4141E-12 0.00071738"
        rpy="0 0 0" />
      <mass
        value="0.064652" />
      <inertia
        ixx="1.1916E-05"
        ixy="1.4608E-15"
        ixz="3.2612E-07"
        iyy="1.8721E-05"
        iyz="5.2081E-15"
        izz="1.3966E-05" />
    </inertial>
    <visual>
      <origin
        xyz="0 0 0"
        rpy="0 0 0" />
      <geometry>
        <mesh
          filename="package://robotpincher/meshes/Link3.STL" />
      </geometry>
      <material
        name="">
        <color
          rgba="0.79216 0.81961 0.93333 1" />
      </material>
    </visual>
    <collision>
      <origin
        xyz="0 0 0"
        rpy="0 0 0" />
      <geometry>
        <mesh
          filename="package://robotpincher/meshes/Link3.STL" />
      </geometry>
    </collision>
  </link>
  <joint
    name="Joint3"
    type="revolute">
    <origin
      xyz="0.10798 0 0"
      rpy="0 0 0" />
    <parent
      link="Link2" />
    <child
      link="Link3" />
    <axis
      xyz="0 0 -1" />
    <limit
      lower="-1.570"
      upper="1.570"
      effort="1000"
      velocity="0.5" />
  </joint>

<transmission name="tran3">
    <type>transmission_interface/SimpleTransmission</type>
    <joint name="Joint3">
	<hardwareInterface>EffortJointInterface</hardwareInterface>
    </joint>
    <actuator name="motor3">
      <hardwareInterface>EffortJointInterface</hardwareInterface>
      <mechanicalReduction>1</mechanicalReduction>
    </actuator>
  </transmission>

  <link
    name="Link4">
    <inertial>
      <origin
        xyz="0.044275 -0.010475 4.2545E-05"
        rpy="0 0 0" />
      <mass
        value="0.055887" />
      <inertia
        ixx="1.397E-05"
        ixy="2.6941E-07"
        ixz="3.839E-08"
        iyy="9.7406E-06"
        iyz="1.461E-15"
        izz="1.3925E-05" />
    </inertial>
    <visual>
      <origin
        xyz="0 0 0"
        rpy="0 0 0" />
      <geometry>
        <mesh
          filename="package://robotpincher/meshes/Link4.STL" />
      </geometry>
      <material
        name="">
        <color
          rgba="0.79216 0.81961 0.93333 1" />
      </material>
    </visual>
    <collision>
      <origin
        xyz="0 0 0"
        rpy="0 0 0" />
      <geometry>
        <mesh
          filename="package://robotpincher/meshes/Link4.STL" />
      </geometry>
    </collision>
  </link>
  <joint
    name="Joint4"
    type="revolute">
    <origin
      xyz="0.10798 0 0"
      rpy="0 0 0" />
    <parent
      link="Link3" />
    <child
      link="Link4" />
    <axis
      xyz="0 0 -1" />
    <limit
      lower="-1.5708"
      upper="1.5708"
      effort="1000"
      velocity="0.5" />
  </joint>

  <transmission name="tran4">
    <type>transmission_interface/SimpleTransmission</type>
    <joint name="Joint4">
	<hardwareInterface>EffortJointInterface</hardwareInterface>
    </joint>
    <actuator name="motor4">
      <hardwareInterface>EffortJointInterface</hardwareInterface>
      <mechanicalReduction>1</mechanicalReduction>
    </actuator>
  </transmission>

  <link
    name="Link5">
    <inertial>
      <origin
        xyz="-0.032112 -0.00040962 1.7381E-15"
        rpy="0 0 0" />
      <mass
        value="0.021767" />
      <inertia
        ixx="7.4327E-06"
        ixy="-2.4046E-08"
        ixz="-3.7014E-20"
        iyy="5.6772E-06"
        iyz="-1.388E-21"
        izz="5.5543E-06" />
    </inertial>
    <visual>
      <origin
        xyz="0 0 0"
        rpy="0 0 0" />
      <geometry>
        <mesh
          filename="package://robotpincher/meshes/Link5.STL" />
      </geometry>
      <material
        name="">
        <color
          rgba="0.79216 0.81961 0.93333 1" />
      </material>
    </visual>
    <collision>
      <origin
        xyz="0 0 0"
        rpy="0 0 0" />
      <geometry>
        <mesh
          filename="package://robotpincher/meshes/Link5.STL" />
      </geometry>
    </collision>
  </link>
  <joint
    name="Joint5"
    type="fixed">
    <origin
      xyz="0.11145 0.00105 0"
      rpy="0 0 0" />
    <parent
      link="Link4" />
    <child
      link="Link5" />
    <axis
      xyz="0 0 0" />
    <limit
      lower="0"
      upper="0"
      effort="0"
      velocity="0" />
  </joint>

 

</robot>
